<?xml version='1.0'?>

<robot name="avular_origin_v10">

    <material name="blue">
        <color rgba="0.2 0.2 1 1"/>
    </material>

    <!-- Main Body -->
    <link name='main_body'>
        <inertial>
            <mass value="21.0"/>
            <inertia ixx="0.4" ixy="0.0" ixz="0.0" iyy="0.77" iyz="0.0" izz="1.01"/>
        </inertial>
        <collision name='main_body_collision'>
            <origin xyz="0 0 0.3175" rpy="0 0 0.0"/>
            <geometry>
                <box size=".65 .4 .125"/>
            </geometry>
        </collision>
        <visual name='main_body_visual'>
            <origin xyz="0 0 0.3175" rpy="0 0 0.0"/>
            <geometry>
                <box size=".65 .4 .125"/>
            </geometry>
            <material name="blue"/>
        </visual>
    </link>


    <!-- Main Body to Left Front Passive Arm -->
    <joint type="revolute" name="main_body_left_front_passive_arm_joint">
        <origin xyz="0.205 0.2 0.3175" rpy="0 0 0"/>
        <parent link="main_body"/>
        <child link="left_front_passive_arm"/>
        <axis xyz="0 1 0"/>
        <dynamics damping="0.1" stiffness="0.5"/>
        <limit effort="100000.0" velocity="10" lower="-1.5708" upper="1.5708"/>
    </joint>


    <!-- Left Front Passive Arm -->
    <link name="left_front_passive_arm">
        <inertial>
            <mass value="1.0"/>
            <inertia ixx="0.001" ixy="0.0" ixz="0.0" iyy="0.001" iyz="0.0" izz="0.001"/>
        </inertial>
        <collision name="left_front_passive_arm_collision">
            <origin xyz="0.0 0.02 -0.1" rpy="0 0 0"/>
            <geometry>
                <box size="0.1 0.04 0.3"/>
            </geometry>
        </collision>
        <visual name="left_front_passive_arm_visual">
            <origin xyz="0.0 0.02 -0.1" rpy="0 0 0"/>
            <geometry>
                <box size="0.1 0.04 0.3"/>
            </geometry>
        </visual>
    </link>


    <!-- Left Front Passive Arm to Left Front Wheel -->
    <joint type="continuous" name="left_front_passive_arm_left_front_wheel_joint">
        <origin xyz="0 0.04 -0.2" rpy="-1.5707 0 0"/>
        <parent link="left_front_passive_arm"/>
        <child link="left_front_wheel"/>
        <axis xyz="0 1 0"/>
        <dynamics damping="0.1" stiffness="0.5"/>
        <limit effort="100000.0" velocity="10" lower="-1.5708" upper="1.5708"/>
    </joint>


    <link name="left_front_wheel">
        <inertial>
            <mass value="1"/>
            <inertia ixx="0.01" ixy="0.0" ixz="0.0" iyy="0.01" iyz="0.0" izz="0.01"/>
        </inertial>
        <collision name="left_front_wheel_collision">
            <origin xyz="0.0 0.0 0.035" rpy="0 0 0"/>
            <geometry>
                <cylinder length=".07" radius=".1175"/>
            </geometry>
        </collision>
        <visual name="left_front_wheel_visual">
            <origin xyz="0.0 0.0 0.035" rpy="0.0 0.0 0.0"/>
            <geometry>
                <cylinder length=".07" radius=".1175"/>
            </geometry>
        </visual>
    </link>



    <!-- Main Body to Right Front Passive Arm -->
    <joint type="revolute" name="main_body_right_front_passive_arm_joint">
        <origin xyz="0.205 -0.2 0.3175" rpy="0 0 0"/>
        <parent link="main_body"/>
        <child link="right_front_passive_arm"/>
        <axis xyz="0 -1 0"/>
        <dynamics damping="0.1" stiffness="0.5"/>
        <limit effort="100000.0" velocity="10" lower="-1.5708" upper="1.5708"/>
    </joint>


    <!-- Right Front Passive Arm -->
    <link name="right_front_passive_arm">
        <inertial>
            <mass value="1.0"/>
            <inertia ixx="0.001" ixy="0.0" ixz="0.0" iyy="0.001" iyz="0.0" izz="0.001"/>
        </inertial>
        <collision name="right_front_passive_arm_collision">
            <origin xyz="0.0 -0.02 -0.1" rpy="0 0 0"/>
            <geometry>
                <box size="0.1 0.04 0.3"/>
            </geometry>
        </collision>
        <visual name="right_front_passive_arm_visual">
            <origin xyz="0.0 -0.02 -0.1" rpy="0 0 0"/>
            <geometry>
                <box size="0.1 0.04 0.3"/>
            </geometry>
        </visual>
    </link>


    <!-- Right Front Passive Arm to Right Front Wheel -->
    <joint type="continuous" name="right_front_passive_arm_right_front_wheel_joint">
        <origin xyz="0 -0.04 -0.2" rpy="-1.5707 0 0"/>
        <parent link="right_front_passive_arm"/>
        <child link="right_front_wheel"/>
        <axis xyz="0 1 0"/>
        <dynamics damping="0.1" stiffness="0.5"/>
        <limit effort="100000.0" velocity="10" lower="-1.5708" upper="1.5708"/>
    </joint>


    <link name="right_front_wheel">
        <inertial>
            <mass value="1"/>
            <inertia ixx="0.01" ixy="0.0" ixz="0.0" iyy="0.01" iyz="0.0" izz="0.01"/>
        </inertial>
        <collision name="right_front_wheel_collision">
            <origin xyz="0.0 0.0 -0.035" rpy="0 0 0"/>
            <geometry>
                <cylinder length=".07" radius=".1175"/>
            </geometry>
        </collision>
        <visual name="right_front_wheel_visual">
            <origin xyz="0.0 0.0 -0.035" rpy="0 0 0"/>
            <geometry>
                <cylinder length=".07" radius=".1175"/>
            </geometry>
        </visual>
    </link>


    <!-- Main Body to Left Rear Passive Arm -->
    <joint type="revolute" name="main_body_left_rear_passive_arm_joint">
        <origin xyz="-0.205 0.2 0.3175" rpy="0 0 0"/>
        <parent link="main_body"/>
        <child link="left_rear_passive_arm"/>
        <axis xyz="0 1 0"/>
        <dynamics damping="0.1" stiffness="0.5"/>
        <limit effort="100000.0" velocity="10" lower="-1.5708" upper="1.5708"/>
    </joint>


    <!-- Left Rear Passive Arm -->
    <link name="left_rear_passive_arm">
        <inertial>
            <mass value="1.0"/>
            <inertia ixx="0.001" ixy="0.0" ixz="0.0" iyy="0.001" iyz="0.0" izz="0.001"/>
        </inertial>
        <collision name="left_rear_passive_arm_collision">
            <origin xyz="0.0 0.02 -0.1" rpy="0 0 0"/>
            <geometry>
                <box size="0.1 0.04 0.3"/>
            </geometry>
        </collision>
        <visual name="left_rear_passive_arm_visual">
            <origin xyz="0.0 0.02 -0.1" rpy="0 0 0"/>
            <geometry>
                <box size="0.1 0.04 0.3"/>
            </geometry>
        </visual>
    </link>


    <!-- Left Rear Passive Arm to Left Rear Wheel -->
    <joint type="continuous" name="left_rear_passive_arm_left_rear_wheel_joint">
        <origin xyz="0 0.04 -0.2" rpy="-1.5707 0 0"/>
        <parent link="left_rear_passive_arm"/>
        <child link="left_rear_wheel"/>
        <axis xyz="0 1 0"/>
        <dynamics damping="0.1" stiffness="0.5"/>
        <limit effort="100000.0" velocity="10" lower="-1.5708" upper="1.5708"/>
    </joint>


    <link name="left_rear_wheel">
        <inertial>
            <mass value="1"/>
            <inertia ixx="0.01" ixy="0.0" ixz="0.0" iyy="0.01" iyz="0.0" izz="0.01"/>
        </inertial>
            <collision name="left_rear_wheel_collision">
            <origin xyz="0.0 0.0 0.035" rpy="0 0 0"/>
            <geometry>
                <cylinder length=".07" radius=".1175"/>
            </geometry>
        </collision>
        <visual name="left_rear_wheel_visual">
            <origin xyz="0.0 0.0 0.035" rpy="0 0 0"/>
            <geometry>
                <cylinder length=".07" radius=".1175"/>
            </geometry>
        </visual>
    </link>


    <!-- Main Body to Right Rear Passive Arm -->
    <joint type="revolute" name="main_body_right_rear_passive_arm_joint">
        <origin xyz="-0.205 -0.2 0.3175" rpy="0 0 0"/>
        <parent link="main_body"/>
        <child link="right_rear_passive_arm"/>
        <axis xyz="0 -1 0"/>
        <dynamics damping="0.1" stiffness="0.5"/>
        <limit effort="100000.0" velocity="10" lower="-1.5708" upper="1.5708"/>
    </joint>

    <!-- Right Rear Passive Arm -->
    <link name="right_rear_passive_arm">
        <inertial>
            <mass value="1.0"/>
            <inertia ixx="0.001" ixy="0.0" ixz="0.0" iyy="0.001" iyz="0.0" izz="0.001"/>
        </inertial>
        <collision name="right_rear_passive_arm_collision">
            <origin xyz="0.0 -0.02 -0.1" rpy="0 0 0"/>
            <geometry>
                <box size="0.1 0.04 0.3"/>
            </geometry>
        </collision>
        <visual name="right_rear_passive_arm_visual">
            <origin xyz="0.0 -0.02 -0.1" rpy="0 0 0"/>
            <geometry>
                <box size="0.1 0.04 0.3"/>
            </geometry>
        </visual>
    </link>


    <!-- Right Rear Passive Arm to Right Rear Wheel -->
    <joint type="continuous" name="right_rear_passive_arm_right_rear_wheel_joint">
        <origin xyz="0 -0.04 -0.2" rpy="-1.5707 0 0"/>
        <parent link="right_rear_passive_arm"/>
        <child link="right_rear_wheel"/>
        <axis xyz="0 1 0"/>
        <dynamics damping="0.1" stiffness="0.5"/>
        <limit effort="100000.0" velocity="10" lower="-1.5708" upper="1.5708"/>
    </joint>


    <link name="right_rear_wheel">
        <inertial>
            <mass value="1"/>
            <inertia ixx="0.01" ixy="0.0" ixz="0.0" iyy="0.01" iyz="0.0" izz="0.01"/>
        </inertial>
        <collision name="right_rear_wheel_collision">
            <origin xyz="0.0 0.0 -0.035" rpy="0 0 0"/>
            <geometry>
                <cylinder length=".07" radius=".1175"/>
            </geometry>
        </collision>
        <visual name="right_rear_wheel_visual">
            <origin xyz="0.0 0.0 -0.035" rpy="0 0 0"/>
            <geometry>
                <cylinder length=".07" radius=".1175"/>
            </geometry>
        </visual>
    </link>



    <joint type="fixed" name="ouster_platform_joint">
        <origin xyz="0.272 0 0.38" rpy="0 0 0"/>
        <child link="ouster_base" />
        <parent link="main_body"/>
    </joint>


    <link name="ouster_base">
        <inertial>
            <mass value="1"/>
            <inertia ixx="0.001" ixy="0.0" ixz="0.0" iyy="0.001" iyz="0.0" izz="0.001"/>
        </inertial>
        <visual name="ouster_base">
            <geometry>
                <box size="0.1 0.1 0.1"/>
            </geometry>
        </visual>
        <collision name="ouster_base">
            <origin xyz="0.0 0.0 0.05" rpy="0.0 0.0 0.0"/>
            <geometry>
                <box size="0.1 0.1 0.1"/>
            </geometry>
        </collision>
    </link>


    <joint type="fixed" name="lidar_joint_gazebo">
        <origin xyz="0 0 0.035" rpy="0 0 0"/>
        <child link="lidar_link_gazebo" />
        <parent link="ouster_base"/>
    </joint>


    <link name="lidar_link_gazebo">
        <inertial>
            <mass value="0.1"/>
            <inertia ixx="0.001" ixy="0.0" ixz="0.0" iyy="0.001" iyz="0.0" izz="0.001"/>
        </inertial>
        <collision name="lidar_link_gazebo">
            <origin xyz="0 0 0.0" rpy="0 0 0"/>
            <geometry>
                <cylinder length="0.07" radius="0.04"/>
            </geometry>
        </collision>
    </link>

    <joint type="fixed" name="realsense_joint">
        <origin xyz="0.32 0.03 0.3175" rpy="0 0 0"/>
        <child link="camera_link"/>
        <parent link="main_body"/>
    </joint>


    <link name="camera_link">
        <inertial>
            <mass value="0.035"/>
            <inertia ixx="0.001" ixy="0" ixz="0.0" iyy="0.001" iyz="0.0" izz="0.001"/>
        </inertial>
        <collision name="camera_link">
            <origin xyz="0 0.047 0" rpy="0 0 0"/>
            <geometry>
                <box size="0.008 0.13 0.022"/>
            </geometry>
        </collision>
    </link>
 
</robot>
