<?xml version='1.0'?>

<robot name="avular_origin_v12">

    <material name="green">
        <color rgba="0 1 0 1"/>
    </material>

    <!-- Main Body -->
    <link name='main_body_v12'>
        <inertial>
            <mass value="21.0"/>
            <inertia ixx="0.4" ixy="0.0" ixz="0.0" iyy="0.77" iyz="0.0" izz="1.01"/>
        </inertial>
        <collision name='main_body_v12_collision'>
            <origin xyz="0 0 0.3175" rpy="0 0 0.0"/>
            <geometry>
                <box size=".65 .4 .125"/>
            </geometry>
        </collision>
        <visual name='main_body_v12_visual'>
            <origin xyz="0 0 0.3175" rpy="0 0 0.0"/>
            <geometry>
                <box size=".65 .4 .125"/>
            </geometry>
            <material name="green"/>
        </visual>
    </link>


    <!-- Main Body to Left Front Passive Arm -->
    <joint type="revolute" name="left_front_passive_arm_joint_v12">
        <origin xyz="0.205 0.2 0.3175" rpy="0 0 0"/>
        <parent link="main_body_v12"/>
        <child link="left_front_passive_arm_v12"/>
        <axis xyz="0 1 0"/>
        <dynamics damping="5.0" stiffness="150.0"/>
        <limit effort="100000.0" velocity="10" lower="-0.7854" upper="0.0"/>
    </joint>


    <!-- Left Front Passive Arm -->
    <link name="left_front_passive_arm_v12">
        <inertial>
            <mass value="1.0"/>
            <inertia ixx="0.001" ixy="0.0" ixz="0.0" iyy="0.001" iyz="0.0" izz="0.001"/>
        </inertial>
        <collision name="left_front_passive_arm_v12_collision">
            <origin xyz="0.0 0.02 -0.1" rpy="0 0 0"/>
            <geometry>
                <box size="0.1 0.04 0.2"/>
            </geometry>
        </collision>
        <visual name="left_front_passive_arm_v12_visual">
            <origin xyz="0.0 0.02 -0.1" rpy="0 0 0"/>
            <geometry>
                <box size="0.1 0.04 0.2"/>
            </geometry>
        </visual>
    </link>


    <!-- Left Front Passive Arm to Left Front Wheel -->
    <joint type="continuous" name="left_front_wheel_joint_v12">
        <origin xyz="0 0.04 -0.15" rpy="-1.5707 0 0"/>
        <parent link="left_front_passive_arm_v12"/>
        <child link="left_front_wheel_v12"/>
        <axis xyz="0 1 0"/>
        <dynamics damping="0.1" stiffness="0.5"/>
        <limit effort="100000.0" velocity="10"/>
    </joint>


    <link name="left_front_wheel_v12">
        <inertial>
            <mass value="1"/>
            <inertia ixx="0.01" ixy="0.0" ixz="0.0" iyy="0.01" iyz="0.0" izz="0.01"/>
        </inertial>
        <collision name="left_front_wheel_v12_collision">
            <origin xyz="0.0 0.0 0.035" rpy="0 0 0"/>
            <geometry>
                <cylinder length=".07" radius=".2"/>
            </geometry>
        </collision>
        <visual name="left_front_wheel_v12_visual">
            <origin xyz="0.0 0.0 0.035" rpy="0.0 0.0 0.0"/>
            <geometry>
                <cylinder length=".07" radius=".2"/>
            </geometry>
        </visual>
    </link>



    <!-- Main Body to Right Front Passive Arm -->
    <joint type="revolute" name="right_front_passive_arm_joint_v12">
        <origin xyz="0.205 -0.2 0.3175" rpy="0 0 0"/>
        <parent link="main_body_v12"/>
        <child link="right_front_passive_arm_v12"/>
        <axis xyz="0 -1 0"/>
        <dynamics damping="5.0" stiffness="150.0"/>
        <limit effort="100000.0" velocity="10" lower="-0.7854" upper="0.0"/>
    </joint>


    <!-- Right Front Passive Arm -->
    <link name="right_front_passive_arm_v12">
        <inertial>
            <mass value="1.0"/>
            <inertia ixx="0.001" ixy="0.0" ixz="0.0" iyy="0.001" iyz="0.0" izz="0.001"/>
        </inertial>
        <collision name="right_front_passive_arm_v12_collision">
            <origin xyz="0.0 -0.02 -0.1" rpy="0 0 0"/>
            <geometry>
                <box size="0.1 0.04 0.2"/>
            </geometry>
        </collision>
        <visual name="right_front_passive_v12_arm_visual">
            <origin xyz="0.0 -0.02 -0.1" rpy="0 0 0"/>
            <geometry>
                <box size="0.1 0.04 0.2"/>
            </geometry>
        </visual>
    </link>


    <!-- Right Front Passive Arm to Right Front Wheel -->
    <joint type="continuous" name="right_front_wheel_joint_v12">
        <origin xyz="0 -0.04 -0.15" rpy="-1.5707 0 0"/>
        <parent link="right_front_passive_arm_v12"/>
        <child link="right_front_wheel_v12"/>
        <axis xyz="0 1 0"/>
        <dynamics damping="0.1" stiffness="0.5"/>
        <limit effort="100000.0" velocity="10"/>
    </joint>


    <link name="right_front_wheel_v12">
        <inertial>
            <mass value="1"/>
            <inertia ixx="0.01" ixy="0.0" ixz="0.0" iyy="0.01" iyz="0.0" izz="0.01"/>
        </inertial>
        <collision name="right_front_wheel_v12_collision">
            <origin xyz="0.0 0.0 -0.035" rpy="0 0 0"/>
            <geometry>
                <cylinder length=".07" radius=".2"/>
            </geometry>
        </collision>
        <visual name="right_front_wheel_v12_visual">
            <origin xyz="0.0 0.0 -0.035" rpy="0 0 0"/>
            <geometry>
                <cylinder length=".07" radius=".2"/>
            </geometry>
        </visual>
    </link>


    <!-- Main Body to Left Rear Passive Arm -->
    <joint type="revolute" name="rear_passive_arm_joint_v12">
        <origin xyz="-0.205 0.2 0.3175" rpy="0 0 0"/>
        <parent link="main_body_v12"/>
        <child link="left_rear_passive_arm_v12"/>
        <axis xyz="0 1 0"/>
        <dynamics damping="5.0" stiffness="150.0"/>
        <limit effort="100000.0" velocity="10" lower="0.0" upper="0.7854"/>
    </joint>


    <!-- Left Rear Passive Arm -->
    <link name="left_rear_passive_arm_v12">
        <inertial>
            <mass value="1.0"/>
            <inertia ixx="0.001" ixy="0.0" ixz="0.0" iyy="0.001" iyz="0.0" izz="0.001"/>
        </inertial>
        <collision name="left_rear_passive_arm_v12_collision">
            <origin xyz="0.0 0.02 -0.1" rpy="0 0 0"/>
            <geometry>
                <box size="0.1 0.04 0.2"/>
            </geometry>
        </collision>
        <visual name="left_rear_passive_arm_v12_visual">
            <origin xyz="0.0 0.02 -0.1" rpy="0 0 0"/>
            <geometry>
                <box size="0.1 0.04 0.2"/>
            </geometry>
        </visual>
    </link>


    <!-- Left Rear Passive Arm to Left Rear Wheel -->
    <joint type="continuous" name="left_rear_wheel_joint_v12">
        <origin xyz="0 0.04 -0.15" rpy="-1.5707 0 0"/>
        <parent link="left_rear_passive_arm_v12"/>
        <child link="left_rear_wheel_v12"/>
        <axis xyz="0 1 0"/>
        <dynamics damping="0.1" stiffness="0.5"/>
        <limit effort="100000.0" velocity="10"/>
    </joint>


    <link name="left_rear_wheel_v12">
        <inertial>
            <mass value="1"/>
            <inertia ixx="0.01" ixy="0.0" ixz="0.0" iyy="0.01" iyz="0.0" izz="0.01"/>
        </inertial>
            <collision name="left_rear_wheel_v12_collision">
            <origin xyz="0.0 0.0 0.035" rpy="0 0 0"/>
            <geometry>
                <cylinder length=".07" radius=".2"/>
            </geometry>
        </collision>
        <visual name="left_rear_wheel_v12_visual">
            <origin xyz="0.0 0.0 0.035" rpy="0 0 0"/>
            <geometry>
                <cylinder length=".07" radius=".2"/>
            </geometry>
        </visual>
    </link>


    <!-- Main Body to Right Rear Passive Arm -->
    <joint type="revolute" name="right_rear_passive_arm_joint_v12">
        <origin xyz="-0.205 -0.2 0.3175" rpy="0 0 0"/>
        <parent link="main_body_v12"/>
        <child link="right_rear_passive_arm_v12"/>
        <axis xyz="0 -1 0"/>
        <dynamics damping="5.0" stiffness="150.0"/>
        <limit effort="100000.0" velocity="10" lower="0.0" upper="0.7854"/>
    </joint>

    <!-- Right Rear Passive Arm -->
    <link name="right_rear_passive_arm_v12">
        <inertial>
            <mass value="1.0"/>
            <inertia ixx="0.001" ixy="0.0" ixz="0.0" iyy="0.001" iyz="0.0" izz="0.001"/>
        </inertial>
        <collision name="right_rear_passive_arm_v12_collision">
            <origin xyz="0.0 -0.02 -0.1" rpy="0 0 0"/>
            <geometry>
                <box size="0.1 0.04 0.2"/>
            </geometry>
        </collision>
        <visual name="right_rear_passive_arm_v12_visual">
            <origin xyz="0.0 -0.02 -0.1" rpy="0 0 0"/>
            <geometry>
                <box size="0.1 0.04 0.2"/>
            </geometry>
        </visual>
    </link>


    <!-- Right Rear Passive Arm to Right Rear Wheel -->
    <joint type="continuous" name="right_rear_wheel_joint_v12">
        <origin xyz="0 -0.04 -0.15" rpy="-1.5707 0 0"/>
        <parent link="right_rear_passive_arm_v12"/>
        <child link="right_rear_wheel_v12"/>
        <axis xyz="0 1 0"/>
        <dynamics damping="0.1" stiffness="0.5"/>
        <limit effort="100000.0" velocity="10"/>
    </joint>


    <link name="right_rear_wheel_v12">
        <inertial>
            <mass value="1"/>
            <inertia ixx="0.01" ixy="0.0" ixz="0.0" iyy="0.01" iyz="0.0" izz="0.01"/>
        </inertial>
        <collision name="right_rear_wheel_v12_collision">
            <origin xyz="0.0 0.0 -0.035" rpy="0 0 0"/>
            <geometry>
                <cylinder length=".07" radius=".2"/>
            </geometry>
        </collision>
        <visual name="right_rear_wheel_v12_visual">
            <origin xyz="0.0 0.0 -0.035" rpy="0 0 0"/>
            <geometry>
                <cylinder length=".07" radius=".2"/>
            </geometry>
        </visual>
    </link>



    <joint type="fixed" name="ouster_platform_joint_v12">
        <origin xyz="0.272 0 0.38" rpy="0 0 0"/>
        <child link="ouster_base_v12" />
        <parent link="main_body_v12"/>
    </joint>


    <link name="ouster_base_v12">
        <inertial>
            <mass value="1"/>
            <inertia ixx="0.001" ixy="0.0" ixz="0.0" iyy="0.001" iyz="0.0" izz="0.001"/>
        </inertial>
        <visual name="ouster_base_v12_visual">
            <origin xyz="0.0 0.0 0.05" rpy="0.0 0.0 0.0"/>
            <geometry>
                <box size="0.1 0.1 0.1"/>
            </geometry>
        </visual>
        <collision name="ouster_base_v12_collision">
            <origin xyz="0.0 0.0 0.05" rpy="0.0 0.0 0.0"/>
            <geometry>
                <box size="0.1 0.1 0.1"/>
            </geometry>
        </collision>
    </link>


    <joint type="fixed" name="lidar_joint_gazebo_v12">
        <origin xyz="0 0 0.035" rpy="0 0 0"/>
        <child link="lidar_link_gazebo_v12" />
        <parent link="ouster_base_v12"/>
    </joint>


    <link name="lidar_link_gazebo_v12">
        <inertial>
            <mass value="0.1"/>
            <inertia ixx="0.001" ixy="0.0" ixz="0.0" iyy="0.001" iyz="0.0" izz="0.001"/>
        </inertial>
        <collision name="lidar_link_gazebo_v12_collision">
            <origin xyz="0 0 0.0" rpy="0 0 0"/>
            <geometry>
                <cylinder length="0.07" radius="0.04"/>
            </geometry>
        </collision>
    </link>

    <joint type="fixed" name="realsense_joint_v12">
        <origin xyz="0.32 0.03 0.3175" rpy="0 0 0"/>
        <child link="camera_link_v12"/>
        <parent link="main_body_v12"/>
    </joint>


    <link name="camera_link_v12">
        <inertial>
            <mass value="0.035"/>
            <inertia ixx="0.001" ixy="0" ixz="0.0" iyy="0.001" iyz="0.0" izz="0.001"/>
        </inertial>
        <collision name="camera_link_v12_collision">
            <origin xyz="0 0.047 0" rpy="0 0 0"/>
            <geometry>
                <box size="0.008 0.13 0.022"/>
            </geometry>
        </collision>
    </link>
 
</robot>
