<?xml version='1.0'?>

<robot name="avular_origin_v10">

  <material name="grey">
    <color rgba="0.2 0.2 0.2 1"/>
  </material>

  <link name='main_body'>
    <inertial>
      <mass value="21.0"/>
      <inertia ixx="0.4" ixy="0.0" ixz="0.0" iyy="0.77" iyz="0.0" izz="1.01"/>
    </inertial>
    <collision name='main_body_collision'>
      <origin xyz="0 0 0.07" rpy="0 0 0.0"/>
      <geometry>
        <box size=".65 .4 .125"/>
      </geometry>
    </collision>
    <visual name='main_body_visual'>
      <origin xyz="0 0 0.07" rpy="0 0 0.0"/>
      <geometry>
        <box size=".65 .4 .125"/>
      </geometry>
      <material name="black"/>
    </visual>
  </link>

 
  <link name="left_front_wheel">
    <inertial>
      <mass value="1"/>
      <inertia ixx="0.01" ixy="0.0" ixz="0.0" iyy="0.01" iyz="0.0" izz="0.01"/>
    </inertial>
    <collision name="left_front_wheel_collision">
      <origin xyz="0 0 0.0" rpy="0 0 0"/>
      <geometry>
        <cylinder length=".07" radius=".1175"/>
      </geometry>
    </collision>
    <visual name="left_front_wheel_visual">
      <origin xyz="0.0 0.0 0.0" rpy="0.0 0.0 0.0"/>
      <geometry>
        <cylinder length=".07" radius=".1175"/>
      </geometry>
    </visual>
  </link>

  <link name="right_front_wheel">
    <inertial>
      <mass value="1"/>
      <inertia ixx="0.01" ixy="0.0" ixz="0.0" iyy="0.01" iyz="0.0" izz="0.01"/>
    </inertial>
    <collision name="right_front_wheel_collision">
      <origin xyz="0 0 0.0" rpy="0 0 0"/>
      <geometry>
        <cylinder length=".07" radius=".1175"/>
      </geometry>
    </collision>
    <visual name="right_front_wheel_visual">
      <origin xyz="0.0 0.0 0.0" rpy="0.0 0.0 0.0"/>
      <geometry>
        <cylinder length=".07" radius=".1175"/>
      </geometry>
    </visual>
  </link>

  <link name="left_rear_wheel">
    <inertial>
      <mass value="1"/>
      <inertia ixx="0.01" ixy="0.0" ixz="0.0" iyy="0.01" iyz="0.0" izz="0.01"/>
    </inertial>
    <collision name="left_rear_wheel_collision">
      <origin xyz="0 0 0.0" rpy="0 0 0"/>
      <geometry>
        <cylinder length=".07" radius=".1175"/>
      </geometry>
    </collision>
    <visual name="left_rear_wheel_visual">
      <origin xyz="0.0 0.0 0.0" rpy="0.0 0.0 0.0"/>
      <geometry>
        <cylinder length=".07" radius=".1175"/>
      </geometry>
    </visual>
  </link>

  <link name="right_rear_wheel">
    <inertial>
      <mass value="1"/>
      <inertia ixx="0.01" ixy="0.0" ixz="0.0" iyy="0.01" iyz="0.0" izz="0.01"/>
    </inertial>
    <collision name="right_rear_wheel_collision">
      <origin xyz="0 0 0.0" rpy="0 0 0"/>
      <geometry>
        <cylinder length=".07" radius=".1175"/>
      </geometry>
    </collision>
    <visual name="right_rear_wheel_visual">
      <origin xyz="0.0 0.0 0.0" rpy="0.0 0.0 0.0"/>
      <geometry>
        <cylinder length=".07" radius=".1175"/>
      </geometry>
    </visual>
  </link>


  <link name="ouster_base">
    <inertial>
      <mass value="1"/>
      <inertia ixx="0.001" ixy="0.0" ixz="0.0" iyy="0.001" iyz="0.0" izz="0.001"/>
    </inertial>
    <visual name="ouster_base">
      <geometry>
        <box size="0.1 0.1 0.1"/>
      </geometry>
    </visual>
    <collision name="ouster_base">
      <origin xyz="0.0 0.0 0.0" rpy="0.0 0.0 0.0"/>
      <geometry>
        <box size="0.1 0.1 0.1"/>
      </geometry>
    </collision>
  </link>


  <link name="lidar_link_gazebo">
    <inertial>
      <mass value="0.1"/>
      <inertia ixx="0.001" ixy="0.0" ixz="0.0" iyy="0.001" iyz="0.0" izz="0.001"/>
    </inertial>
    <collision name="lidar_link_gazebo">
      <origin xyz="0 0 0.0" rpy="0 0 0"/>
      <geometry>
        <cylinder length="0.07" radius="0.04"/>
      </geometry>
    </collision>
  </link>


  <link name="camera_link">
    <inertial>
      <mass value="0.035"/>
      <inertia ixx="0.001" ixy="0" ixz="0.0" iyy="0.001" iyz="0.0" izz="0.001"/>
    </inertial>
    <collision name="camera_link">
      <origin xyz="0 0.047 0" rpy="0 0 0"/>
      <geometry>
        <box size="0.008 0.13 0.022"/>
      </geometry>
    </collision>
  </link>

  <joint type="continuous" name="left_front_wheel_joint">
    <origin xyz="0.205 0.25 0.056" rpy="-1.5707 0 0"/>
    <child link="left_front_wheel" />
    <parent link="main_body"/>
    <axis xyz="0 0 1"/>
    <limit effort="100000.0" velocity="10"/>
  </joint>

  <joint type="continuous" name="right_front_wheel_joint">
    <origin xyz="0.205 -0.25 0.056" rpy="1.5707 0 0"/>
    <child link="right_front_wheel" />
    <parent link="main_body"/>
    <axis xyz="0 0 -1"/>
    <limit effort="100000.0" velocity="10"/>
  </joint>

  <joint type="continuous" name="eft_rear_wheel_joint">
    <origin xyz="-0.205 0.25 0.056" rpy="-1.5707 0 0"/>
    <child link="left_rear_wheel" />
    <parent link="main_body"/>
    <axis xyz="0 0 1"/>
    <limit effort="100000.0" velocity="10"/>
  </joint>

  <joint type="continuous" name="right_rear_wheel_joint">
    <origin xyz="-0.205 -0.25 0.056" rpy="1.5707 0 0"/>
    <child link="right_rear_wheel" />
    <parent link="main_body"/>
    <axis xyz="0 0 -1"/>
    <limit effort="100000.0" velocity="10"/>
  </joint>

  <joint type="fixed" name="ouster_platform_joint">
    <origin xyz="0.272 0 0.189" rpy="0 0 0"/>
    <child link="ouster_base" />
    <parent link="main_body"/>
  </joint>

  <joint type="fixed" name="lidar_joint_gazebo">
    <origin xyz="0 0 0.035" rpy="0 0 0"/>
    <child link="lidar_link_gazebo" />
    <parent link="ouster_base"/>
  </joint>

  <joint type="fixed" name="realsense_joint">
    <origin xyz="0.32 0.03 0.1" rpy="0 0 0"/>
    <child link="camera_link"/>
    <parent link="main_body"/>
  </joint>


</robot>
