<?xml version='1.0'?>

<robot name="avular_origin_v11">


  <link name='main_body'>
    <inertial>
      <mass value="21.0"/>
      <inertia ixx="0.4" ixy="0.0" ixz="0.0" iyy="0.77" iyz="0.0" izz="1.01"/>
    </inertial>
    <collision name='collision'>
      <origin xyz="0 0 0.07" rpy="0 0 0.0"/>
      <geometry>
        <box size=".65 .4 .125"/>
      </geometry>
    </collision>
    <visual name='visual'>
      <origin xyz="0 0 0.07" rpy="0 0 0.0"/>
      <geometry>
        <box size=".65 .4 .125"/>
      </geometry>
      <material name="main_body_color">
        <color rgba="1 0 0 1"/>  <!-- RED -->
      </material>
    </visual>
  </link>

  <link name="left_front_wheel">
    <inertial>
      <mass value="1"/>
      <inertia ixx="0.01" ixy="0.0" ixz="0.0" iyy="0.01" iyz="0.0" izz="0.01"/>
    </inertial>
    <collision>
      <origin xyz="0 0 0.0" rpy="0 0 0"/>
      <geometry>
        <cylinder length=".07" radius=".2"/>
      </geometry>
    </collision>
    <visual>
      <origin xyz="0.0 0.0 0.0" rpy="0.0 0.0 0.0"/>
      <geometry>
        <cylinder length=".07" radius=".2"/>
      </geometry>
      <material name="left_front_wheel_color">
        <color rgba="0 0 0 1"/>  <!-- Black -->
      </material>
    </visual>
  </link>


  <link name="right_front_wheel">
    <inertial>
      <mass value="1"/>
      <inertia ixx="0.01" ixy="0.0" ixz="0.0" iyy="0.01" iyz="0.0" izz="0.01"/>
    </inertial>
    <collision>
      <origin xyz="0 0 0.0" rpy="0 0 0"/>
      <geometry>
        <cylinder length=".07" radius=".2"/>
      </geometry>
    </collision>
    <visual>
      <origin xyz="0.0 0.0 0.0" rpy="0.0 0.0 0.0"/>
      <geometry>
        <cylinder length=".07" radius=".2"/>
      </geometry>
      <material name="right_front_wheel_color">
        <color rgba="0 0 0 1"/>  <!-- Black -->
      </material>
    </visual>
  </link>

  <link name="left_rear_wheel">
    <inertial>
      <mass value="1"/>
      <inertia ixx="0.01" ixy="0.0" ixz="0.0" iyy="0.01" iyz="0.0" izz="0.01"/>
    </inertial>
    <collision>
      <origin xyz="0 0 0.0" rpy="0 0 0"/>
      <geometry>
        <cylinder length=".07" radius=".2"/>
      </geometry>
    </collision>
    <visual>
      <origin xyz="0.0 0.0 0.0" rpy="0.0 0.0 0.0"/>
      <geometry>
        <cylinder length=".07" radius=".2"/>
      </geometry>
      <material name="left_rear_wheel_color">
        <color rgba="0 0 0 1"/>  <!-- Black -->
      </material>
    </visual>
  </link>

  <link name="right_rear_wheel">
    <inertial>
      <mass value="1"/>
      <inertia ixx="0.01" ixy="0.0" ixz="0.0" iyy="0.01" iyz="0.0" izz="0.01"/>
    </inertial>
    <collision>
      <origin xyz="0 0 0.0" rpy="0 0 0"/>
      <geometry>
        <cylinder length=".07" radius=".2"/>
      </geometry>
    </collision>
    <visual>
      <origin xyz="0.0 0.0 0.0" rpy="0.0 0.0 0.0"/>
      <geometry>
        <cylinder length=".07" radius=".2"/>
      </geometry>
      <material name="right_rear_wheel_color">
        <color rgba="0 0 0 1"/>  <!-- Black -->
      </material>
    </visual>
  </link>



  <link name="ouster_base">
    <inertial>
      <mass value="1"/>
      <inertia ixx="0.001" ixy="0.0" ixz="0.0" iyy="0.001" iyz="0.0" izz="0.001"/>
    </inertial>
    <visual name="visual">
      <geometry>
        <box size="0.1 0.1 0.1"/>
      </geometry>
      <material name="ouster_base_color">
        <color rgba="1 1 1 1"/>  <!-- White -->
      </material>
    </visual>
    <collision name="collision-base">
      <origin xyz="0.0 0.0 0.0" rpy="0.0 0.0 0.0"/>
      <geometry>
        <box size="0.1 0.1 0.1"/>
      </geometry>
    </collision>
  </link>


  <link name="lidar_link_gazebo">
    <inertial>
      <mass value="0.1"/>
      <inertia ixx="0.001" ixy="0.0" ixz="0.0" iyy="0.001" iyz="0.0" izz="0.001"/>
    </inertial>
    <collision name="collision-base">
      <origin xyz="0 0 0.0" rpy="0 0 0"/>
      <geometry>
        <cylinder length="0.07" radius="0.04"/>
      </geometry>
    </collision>
  </link>


  <link name="camera_link">
    <inertial>
      <mass value="0.035"/>
      <inertia ixx="0.001" ixy="0" ixz="0.0" iyy="0.001" iyz="0.0" izz="0.001"/>
    </inertial>
    <collision name="collision">
      <origin xyz="0 0.047 0" rpy="0 0 0"/>
      <geometry>
        <box size="0.008 0.13 0.022"/>
      </geometry>
    </collision>
  </link>

  <joint type="continuous" name="main_body_left_front_wheel">
    <origin xyz="0.205 0.25 0.056" rpy="-1.5707 0 0"/>
    <child link="left_front_wheel" />
    <parent link="main_body"/>
    <axis xyz="0 0 1"/>
    <limit effort="100000.0" velocity="10"/>
  </joint>

  <joint type="continuous" name="main_body_right_front_wheel">
    <origin xyz="0.205 -0.25 0.056" rpy="1.5707 0 0"/>
    <child link="right_front_wheel" />
    <parent link="main_body"/>
    <axis xyz="0 0 -1"/>
    <limit effort="100000.0" velocity="10"/>
  </joint>

  <joint type="continuous" name="main_body_left_rear_wheel">
    <origin xyz="-0.205 0.25 0.056" rpy="-1.5707 0 0"/>
    <child link="left_rear_wheel" />
    <parent link="main_body"/>
    <axis xyz="0 0 1"/>
    <limit effort="100000.0" velocity="10"/>
  </joint>

  <joint type="continuous" name="main_body_right_rear_wheel">
    <origin xyz="-0.205 -0.25 0.056" rpy="1.5707 0 0"/>
    <child link="right_rear_wheel" />
    <parent link="main_body"/>
    <axis xyz="0 0 -1"/>
    <limit effort="100000.0" velocity="10"/>
  </joint>

  <joint type="fixed" name="ouster_platform_joint">
    <origin xyz="0.272 0 0.189" rpy="0 0 0"/>
    <child link="ouster_base" />
    <parent link="main_body"/>
  </joint>

  <joint type="fixed" name="lidar_joint_gazebo">
    <origin xyz="0 0 0.035" rpy="0 0 0"/>
    <child link="lidar_link_gazebo" />
    <parent link="ouster_base"/>
  </joint>

  <joint type="fixed" name="realsense_joint">
    <origin xyz="0.32 0.03 0.1" rpy="0 0 0"/>
    <child link="camera_link"/>
    <parent link="main_body"/>
  </joint>


</robot>
