<?xml version="1.0"?>
<robot name="symmetric_skid_steer">

  <!-- Define custom materials -->
  <material name="anthracite">
    <color rgba="0.02 0.02 0.02 1"/>
  </material>

  <material name="rubber_gray">
    <color rgba="0.1 0.1 0.1 1"/>
  </material>

  <material name="dark_red">
    <color rgba="0.8 0.0 0.0 1"/>
  </material>
  
  <material name="black">
    <color rgba="0 0 0 1"/>
  </material>

  <!-- Base Link: COM is at the geometric center -->
  <link name="main_body">
    <inertial>
      <mass value="21.0"/>
      <inertia ixx="0.4" ixy="0.0" ixz="0.0" iyy="0.77" iyz="0.0" izz="1.01"/>
    </inertial>
    <!-- Visual and collision geometries are centered -->
    <visual name="main_body_visual">
      <origin xyz="0 0 0.07" rpy="0 0 0"/>
      <geometry>
        <mesh filename="../meshes/body.obj"
          scale="0.001 0.001 0.001" />
      </geometry>
      <material name="anthracite"/>
    </visual>
    <collision name="main_body_collision">
      <origin xyz="0 0 0.07" rpy="0 0 0.0"/>
      <geometry>
        <box size=".65 .4 .125"/>
      </geometry>
      <material name="red"/>
    </collision>
  </link>

  <!-- Left Front Wheel -->
  <link name="left_front_wheel">
    <inertial>
      <!-- Inertial origin is at the joint location relative to the base -->
      <mass value="1.0"/>
      <inertia ixx="0.01" ixy="0.0" ixz="0.0" iyy="0.01" iyz="0.0" izz="0.01"/>
    </inertial>
    <visual name="left_front_wheel_visual">
      <origin xyz="0 0 0" rpy="0 0 0"/>
      <geometry>
        <mesh filename="../meshes/wheel.obj"
          scale="0.001 0.001 0.001" />
      </geometry>
      <material name="anthracite"/>
    </visual>
    <collision name="left_front_wheel_collision">
      <origin xyz="0 0 0" rpy="0 0 1.5708"/>
      <geometry>
        <cylinder length="0.07" radius="0.1175"/>
      </geometry>
    </collision>
  </link>

  <!-- Right Front Wheel -->
  <link name="right_front_wheel">
    <inertial>
      <mass value="1.0"/>
      <inertia ixx="0.01" ixy="0.0" ixz="0.0" iyy="0.01" iyz="0.0" izz="0.01"/>
    </inertial>
    <visual name="right_front_wheel_visual">
      <origin xyz="0 0 0" rpy="0 0 0"/>
      <geometry>
        <mesh filename="../meshes/wheel.obj"
          scale="0.001 0.001 0.001" />
      </geometry>
      <material name="anthracite"/>
    </visual>
    <collision name="right_front_wheel_collision">
      <origin xyz="0 0 0" rpy="0 0 0"/>
      <geometry>
        <cylinder length="0.07" radius="0.1175"/>
      </geometry>
    </collision>
  </link>

  <!-- Left Rear Wheel -->
  <link name="left_rear_wheel">
    <inertial>
      <mass value="1.0"/>
      <inertia ixx="0.01" ixy="0.0" ixz="0.0" iyy="0.01" iyz="0.0" izz="0.01"/>
    </inertial>
    <visual name="left_rear_wheel_visual">
      <origin xyz="0 0 0" rpy="0 0 0"/>
      <geometry>
        <mesh filename="../meshes/wheel.obj"
          scale="0.001 0.001 0.001" />
      </geometry>
      <material name="anthracite"/>
    </visual>
    <collision name="left_rear_wheel_collision">
      <origin xyz="0 0 0" rpy="0 0 0"/>
      <geometry>
        <cylinder length="0.07" radius="0.1175"/>
      </geometry>
    </collision>
  </link>

  <!-- Right Rear Wheel -->
  <link name="right_rear_wheel">
    <inertial>
      <mass value="1.0"/>
      <inertia ixx="0.01" ixy="0.0" ixz="0.0" iyy="0.01" iyz="0.0" izz="0.01"/>
    </inertial>
    <visual name="right_rear_wheel_visual">
      <origin xyz="0 0 0" rpy="0 0 0"/>
      <geometry>
        <mesh filename="../meshes/wheel.obj"
          scale="0.001 0.001 0.001" />
      </geometry>
      <material name="anthracite"/>
    </visual>
    <collision name="right_rear_wheel_collision">
      <origin xyz="0 0 0" rpy="0 0 0"/>
      <geometry>
        <cylinder length="0.07" radius="0.1175"/>
      </geometry>
    </collision>
  </link>

  <!-- Joints: All defined with symmetric origins relative to the base -->
  <joint name="left_front_wheel_joint" type="continuous">
    <parent link="main_body"/>
    <child link="left_front_wheel"/>
    <origin xyz="0.205 0.25 0.056" rpy="-1.5707 0 0"/>
    <axis xyz="0 0 1"/>
    <limit effort="100000.0" velocity="10"/>
  </joint>

  <joint name="right_front_wheel_joint" type="continuous">
    <parent link="main_body"/>
    <child link="right_front_wheel"/>
    <origin xyz="0.205 -0.25 0.056" rpy="1.5707 0 0"/>
    <axis xyz="0 0 -1"/>
    <limit effort="100000.0" velocity="10"/>
  </joint>

  <joint name="left_rear_wheel_joint" type="continuous">
    <parent link="main_body"/>
    <child link="left_rear_wheel"/>
    <origin xyz="-0.205 0.25 0.056" rpy="-1.5707 0 0"/>
    <axis xyz="0 0 1"/>
    <limit effort="100000.0" velocity="10"/>
  </joint>

  <joint name="right_rear_wheel_joint" type="continuous">
    <parent link="main_body"/>
    <child link="right_rear_wheel"/>
    <origin xyz="-0.205 -0.25 0.056" rpy="1.5707 0 0"/>
    <axis xyz="0 0 -1"/>
    <limit effort="100000.0" velocity="10"/>
  </joint>
</robot>
